<!DOCTYPE html>
<html lang="en">

<head>
    <meta charset="UTF-8">
    <meta http-equiv="X-UA-Compatible" content="IE=edge">
    <meta name="viewport" content="width=device-width, initial-scale=1.0">
    <title>Document</title>
</head>

<body>
    <script>
        /* 
            promise.then(): 
                - 可以捕获promise对象的成功状态，然后再执行下一步回调函数
                - then方法接受一个函数作为参数
                - then的返回值
                    - 如果穿透了(then中不书写回调函数)，则一定返回成功
                    - 如果then内部出现错误信息，则返回失败promise，值为错误信息
                    - 其他情况只要看then回调函数return的promise对象即可
                - then回调函数的参数 就是调用then的成功promise对象的promiseResulte值

            promise.catch():
                - 可以捕获promise对象的失败状态，然后对错误处理
                - catch的返回值：
                    - 如果穿透了(catch中不书写回调函数)，则一定返回失败
                    - 如果catch内部出现错误信息，则返回失败promise，值为错误信息
                    - 其他情况只要看catch回调函数return的promise对象即可
                - catch回调函数的参数 就是调用catch的失败promise对象的promiseResulte值

            promise.finally():
                - 可以捕获成功或失败的promise状态，一般作为整个promise异步操作的最后异步
            promise.then和catch如果不书写任何参数，则会直接把调用then或catch的promise对象穿透过来并返回
         */

        //创建一个Promise
        const p1 = new Promise((resolve, reject) => {
            //这个位置是同步
            console.log("promise内部")
            //请求数据（异步） 把异步代码写入promise中来处理
            setTimeout(() => {
                console.log("请求A数据");
                /* resolve({
                    name: "广东"
                }) */
                reject("error:你失败了");
            }, 1000)
        });
        console.log(p1);


        //当p1收到反馈的时候，则可以继续再执行
        /* const p2 = p1.then((data) => {
            //当p1是一个成功状态的时候，即可执行then中的回调函数
            console.log(data);

            // throw new Error("error");

            //所以可以在这个位置书写第二个异步
            return new Promise((resolve, reject) => {
                setTimeout(() => {
                    console.log("请求B数据");
                    // resolve("B数据");
                    // reject("B Error")
                }, 1000)
            })

        })
        console.log(p2) */


        /* const p3 = p1.catch((err) => {
            console.log(err);
            //假如还需要继续异步的话

            return new Promise((resolve, reject) => {
                reject(1);
            })
        });
        console.log(p3) */


        const p4 = p1.finally((a) => {
            return new Promise((resolve, reject) => {
                resolve(1);
            })
        });
        console.log(p4)
    </script>
</body>

</html>